Workbook
Name IQ_CH: 110000
Name IQ_CQ: 5000
Name IQ_CY: 10000
Name IQ_DAILY: 500000
Name IQ_FH: 100000
Name IQ_FQ: 500
Name IQ_FY: 1000
Name IQ_LTM: 2000
Name IQ_MONTH: 15000
Name IQ_NTM: 6000
Name IQ_WEEK: 50000
Name IQ_YTD: 3000
Name UPDATE: 'Data Sheet'!$E$1

Sheet Data>

Sheet Football Field Analysis
L4: Fooball Field Analysis - Data
N5: Open Low | O5: Low | P5: Open High | Q5: High
L6: Relative Valuation | N6: 3996.3478 | O6: =N6 -> 3996.3478 | P6: 4543.4868 | Q6: =P6 -> 4543.4868
L7: DCF Bear | N7: ='DCF>'!J17 -> 2312.0488 | O7: =N7 -> 2312.0488 | P7: ='DCF>'!J22 -> 3501.4767 | Q7: =P7 -> 3501.4767
L8: DCF Base | N8: ='DCF>'!H17 -> 2719.2986 | O8: =N8 -> 2719.2986 | P8: ='DCF>'!H22 -> 4633.7206 | Q8: =P8 -> 4633.7206
L9: DCF Bull | N9: ='DCF>'!G17 -> 2774.6041 | O9: =N9 -> 2774.6041 | P9: ='DCF>'!G22 -> 4809.8474 | Q9: =P9 -> 4809.8474
L10: 52 Weeks Range | N10: 3288 | O10: =N10 -> 3288 | P10: 4440 | Q10: =P10 -> 4440

Sheet VAR
B1: 10 Year -Daily
B3: Date | C3: Price | D3: Returns | E3: Shorted Returns | G3: Replication | H3: Simulated Returns | J3: ="Calculation of Value at Risk - "& 'Data Sheet'!B1&" (Historical)" -> Calculation of Value at Risk - LARSEN & TOUBRO LTD (Historical)
B4: 07/30/2026 | C4: 3937.7 | D4: =(C4-C5)/C5 -> 0.0016024826 | E4: 0.094096579 | G4: 1 | H4: =_xlfn.NORM.INV(RAND(),N$6,N$7) -> -0.012125798
B5: 07/29/2026 | C5: 3931.4 | D5: =(C5-C6)/C6 -> 0.025939457 | E5: 0.086503906 | G5: 2 | H5: =_xlfn.NORM.INV(RAND(),N$6,N$7) -> 0.01784323 | J5: Historical Approach
B6: 07/28/2026 | C6: 3832 | D6: =(C6-C7)/C7 -> 0.006831319 | E6: 0.080221478 | G6: 3 | H6: =_xlfn.NORM.INV(RAND(),N$6,N$7) -> 0.01400992 | J6: Mean | N6: =AVERAGE(E4:E2478) -> 0.0035224209
B7: 07/27/2026 | C7: 3806 | D7: =(C7-C8)/C8 -> 0.0053888419 | E7: 0.075501428 | G7: 4 | H7: =_xlfn.NORM.INV(RAND(),N$6,N$7) -> 0.014040339 | J7: Std | N7: =_xlfn.STDEV.S(E4:E2478) -> 0.012256623
B8: 07/24/2026 | C8: 3785.6 | D8: =(C8-C9)/C9 -> -0.0017930598 | E8: 0.071999046 | G8: 5 | H8: =_xlfn.NORM.INV(RAND(),N$6,N$7) -> 0.0080153438 | J8: Min | N8: =MIN(E4:E2478) -> -0.016003174
B9: 07/23/2026 | C9: 3792.4 | D9: =(C9-C10)/C10 -> -0.00654896 | E9: 0.062391824 | G9: 6 | H9: =_xlfn.NORM.INV(RAND(),N$6,N$7) -> 0.0047300757 | J9: Max | N9: =MAX(E4:E2478) -> 0.094096579
B10: 07/22/2026 | C10: 3817.4 | D10: =(C10-C11)/C11 -> -0.0075911194 | E10: 0.060686915 | G10: 7 | H10: =_xlfn.NORM.INV(RAND(),N$6,N$7) -> 0.011341558 | J10: current Price | N10: ='Data Sheet'!B8 -> 3785.6
B11: 07/21/2026 | C11: 3846.6 | D11: =(C11-C12)/C12 -> 0.002031885 | E11: 0.060481307 | G11: 8 | H11: =_xlfn.NORM.INV(RAND(),N$6,N$7) -> 0.0085811305
B12: 07/20/2026 | C12: 3838.8 | D12: =(C12-C13)/C13 -> 0.0063704286 | E12: 0.059315661 | G12: 9 | H12: =_xlfn.NORM.INV(RAND(),N$6,N$7) -> -0.011724082 | J12: Percentile | K12: Confidence | L12: VAR% | M12: Stock Price | N12: VAR(INR)
B13: 07/17/2026 | C13: 3814.5 | D13: =(C13-C14)/C14 -> 0.010302998 | E13: 0.053850661 | G13: 10 | H13: =_xlfn.NORM.INV(RAND(),N$6,N$7) -> 0.0066106083 | J13: 0.05 | K13: =100%-J13 -> 0.95 | L13: =_xlfn.PERCENTILE.INC($E$4:$E$2746,J13) -> -0.012453054 | M13: =$N$10*(1-L13) -> 3832.7423 | N13: =$N$10-M13 -> -47.142283
B14: 07/16/2026 | C14: 3775.6 | D14: =(C14-C15)/C15 -> -0.0021935041 | E14: 0.053000817 | G14: 11 | H14: =_xlfn.NORM.INV(RAND(),N$6,N$7) -> 0.031704749 | J14: 0.01 | K14: =100%-J14 -> 0.99 | L14: =_xlfn.PERCENTILE.INC($E$4:$E$2746,J14) -> -0.015081558 | M14: =$N$10*(1-L14) -> 3842.6927 | N14: =$N$10-M14 -> -57.092747
B15: 07/15/2026 | C15: 3783.9 | D15: =(C15-C16)/C16 -> -0.016836854 | E15: 0.050872278 | G15: 12 | H15: =_xlfn.NORM.INV(RAND(),N$6,N$7) -> -0.0015525142 | J15: 0.005 | K15: =100%-J15 -> 0.995 | L15: =_xlfn.PERCENTILE.INC($E$4:$E$2746,J15) -> -0.015387607 | M15: =$N$10*(1-L15) -> 3843.8513 | N15: =$N$10-M15 -> -58.251325
B16: 07/14/2026 | C16: 3848.7 | D16: =(C16-C17)/C17 -> -0.020313097 | E16: 0.04893431 | G16: 13 | H16: =_xlfn.NORM.INV(RAND(),N$6,N$7) -> -0.012045678
B17: 07/13/2026 | C17: 3928.5 | D17: =(C17-C18)/C18 -> -0.0043844087 | E17: 0.048096527 | G17: 14 | H17: =_xlfn.NORM.INV(RAND(),N$6,N$7) -> 0.015729545 | J17: Monte Carlo Simulation
B18: 46302 | C18: 3945.8 | D18: =(C18-C19)/C19 -> 0.015388574 | E18: 0.048056312 | G18: 15 | H18: =_xlfn.NORM.INV(RAND(),N$6,N$7) -> 0.010613962 | J18: Mean | N18: =AVERAGE(H4:H5003) -> 0.0035557497
B19: 46272 | C19: 3886 | D19: =(C19-C20)/C20 -> -0.0015672773 | E19: 0.047002316 | G19: 16 | H19: =_xlfn.NORM.INV(RAND(),N$6,N$7) -> 0.0099819096 | J19: Std | N19: =_xlfn.STDEV.S(H4:H5003) -> 0.012181532
B20: 46241 | C20: 3892.1 | D20: =(C20-C21)/C21 -> -0.025000626 | E20: 0.046593579 | G20: 17 | H20: =_xlfn.NORM.INV(RAND(),N$6,N$7) -> 0.0081370214 | J20: Min | N20: =MIN(H4:H5003) -> -0.040057708
B21: 46210 | C21: 3991.9 | D21: =(C21-C22)/C22 -> -0.012150458 | E21: 0.045199699 | G21: 18 | H21: =_xlfn.NORM.INV(RAND(),N$6,N$7) -> 0.0087044957 | J21: Max | N21: =MAX(H4:H5003) -> 0.051663293
B22: 46180 | C22: 4041 | D22: =(C22-C23)/C23 -> 0.0035762181 | E22: 0.04509434 | G22: 19 | H22: =_xlfn.NORM.INV(RAND(),N$6,N$7) -> 0.0037692558 | J22: current Price | N22: =N10 -> 3785.6
B23: 46088 | C23: 4026.6 | D23: =(C23-C24)/C24 -> -0.0080800118 | E23: 0.044805974 | G23: 20 | H23: =_xlfn.NORM.INV(RAND(),N$6,N$7) -> 0.024983755
B24: 46060 | C24: 4059.4 | D24: =(C24-C25)/C25 -> -0.0081122025 | E24: 0.044711703 | G24: 21 | H24: =_xlfn.NORM.INV(RAND(),N$6,N$7) -> 0.0050183571 | J24: Percentile | K24: Confidence | L24: VAR% | M24: Stock Price | N24: VAR(INR)
B25: 46029 | C25: 4092.6 | D25: =(C25-C26)/C26 -> -0.012260462 | E25: 0.044688134 | G25: 22 | H25: =_xlfn.NORM.INV(RAND(),N$6,N$7) -> 0.025427601 | J25: 0.05 | K25: =100%-J25 -> 0.95 | L25: =_xlfn.PERCENTILE.INC($H$4:$H$5003,J25) -> -0.01641164 | M25: =$N$10*(1-L25) -> 3847.7279 | N25: =$N$10-M25 -> -62.127903
B26: 06/30/2026 | C26: 4143.4 | D26: =(C26-C27)/C27 -> -0.0052338423 | E26: 0.043709948 | G26: 23 | H26: =_xlfn.NORM.INV(RAND(),N$6,N$7) -> -0.0054734791 | J26: 0.01 | K26: =100%-J26 -> 0.99 | L26: =_xlfn.PERCENTILE.INC($H$4:$H$5003,J26) -> -0.024368596 | M26: =$N$10*(1-L26) -> 3877.8498 | N26: =$N$10-M26 -> -92.249757
B27: 06/29/2026 | C27: 4165.2 | D27: =(C27-C28)/C28 -> -0.01214306 | E27: 0.043314073 | G27: 24 | H27: =_xlfn.NORM.INV(RAND(),N$6,N$7) -> -0.0076530851 | J27: 0.005 | K27: =100%-J27 -> 0.995 | L27: =_xlfn.PERCENTILE.INC($H$4:$H$5003,J27) -> -0.02726987 | M27: =$N$10*(1-L27) -> 3888.8328 | N27: =$N$10-M27 -> -103.23282
B28: 06/25/2026 | C28: 4216.4 | D28: =(C28-C29)/C29 -> 0.0082980606 | E28: 0.043241171 | G28: 25 | H28: =_xlfn.NORM.INV(RAND(),N$6,N$7) -> 0.00063914164
B29: 06/24/2026 | C29: 4181.7 | D29: =(C29-C30)/C30 -> 0.00055031823 | E29: 0.042689967 | G29: 26 | H29: =_xlfn.NORM.INV(RAND(),N$6,N$7) -> 0.024409144
B30: 06/23/2026 | C30: 4179.4 | D30: =(C30-C31)/C31 -> -0.0052126723 | E30: 0.042510041 | G30: 27 | H30: =_xlfn.NORM.INV(RAND(),N$6,N$7) -> -0.0011301173
B31: 06/22/2026 | C31: 4201.3 | D31: =(C31-C32)/C32 -> -0.0019242647 | E31: 0.042413309 | G31: 28 | H31: =_xlfn.NORM.INV(RAND(),N$6,N$7) -> 0.0038017802
B32: 06/19/2026 | C32: 4209.4 | D32: =(C32-C33)/C33 -> 0.0046300716 | E32: 0.042215201 | G32: 29 | H32: =_xlfn.NORM.INV(RAND(),N$6,N$7) -> -0.0029591798
B33: 06/18/2026 | C33: 4190 | D33: =(C33-C34)/C34 -> -0.0042065737 | E33: 0.041911211 | G33: 30 | H33: =_xlfn.NORM.INV(RAND(),N$6,N$7) -> 0.0059704404
B34: 06/17/2026 | C34: 4207.7 | D34: =(C34-C35)/C35 -> 0.0050879037 | E34: 0.041232582 | G34: 31 | H34: =_xlfn.NORM.INV(RAND(),N$6,N$7) -> -0.0097958074
B35: 06/16/2026 | C35: 4186.4 | D35: =(C35-C36)/C36 -> 0.0039810063 | E35: 0.041024825 | G35: 32 | H35: =_xlfn.NORM.INV(RAND(),N$6,N$7) -> -0.014133959
B36: 06/15/2026 | C36: 4169.8 | D36: =(C36-C37)/C37 -> 0.02975823 | E36: 0.04047619 | G36: 33 | H36: =_xlfn.NORM.INV(RAND(),N$6,N$7) -> 0.017027969
B37: 46362 | C37: 4049.3 | D37: =(C37-C38)/C38 -> 0.048498187 | E37: 0.039967438 | G37: 34 | H37: =_xlfn.NORM.INV(RAND(),N$6,N$7) -> 0.020588553
B38: 46332 | C38: 3862 | D38: =(C38-C39)/C39 -> -0.014167198 | E38: 0.039910666 | G38: 35 | H38: =_xlfn.NORM.INV(RAND(),N$6,N$7) -> -0.01910954
B39: 46301 | C39: 3917.5 | D39: =(C39-C40)/C40 -> 0.0043326668 | E39: 0.039122237 | G39: 36 | H39: =_xlfn.NORM.INV(RAND(),N$6,N$7) -> 0.0095048142
B40: 46271 | C40: 3900.6 | D40: =(C40-C41)/C41 -> 0.0064765837 | E40: 0.039016569 | G40: 37 | H40: =_xlfn.NORM.INV(RAND(),N$6,N$7) -> 0.00071270819
B41: 46240 | C41: 3875.5 | D41: =(C41-C42)/C42 -> -0.019654963 | E41: 0.038953686 | G41: 38 | H41: =_xlfn.NORM.INV(RAND(),N$6,N$7) -> -0.0036184836
...

Sheet Altman Z Score
B3: ='Data Sheet'!B1 -> LARSEN & TOUBRO LTD
B4: =CONCATENATE("(",_xlfn.XLOOKUP(B3,'List Of Stocks'!B2:B5442,'List Of Stocks'!D2:D5442)," ","|"," ","BSE Code:"," ",_xlfn.XLOOKUP('Altman Z Score'!B3,'List Of Stocks'!B2:B5442,'List Of Stocks'!C2:C5442)," ",")") -> (LT | BSE Code: 500510 )
B5: =CONCATENATE("INR", " ",'Data Sheet'!B8) -> INR 3785.6
B6: ="52 Week" & " "&"("&"High -" & " INR " &'Football Field Analysis'!Q10 & " " &"LOW - " & " INR " &'Football Field Analysis'!N10 &")" -> 52 Week (High - INR 4440 LOW - INR 3288)
B8: Altman's Z Score Analysis
B9: Larsen & Toubro Limited (L&T) is an Indian multinational conglomerate headquartered in Mumbai. It operates in sectors including industrial technology, heavy industry, engineering, construction, manufacturing, power, information technology, defence, and financial services. L&T was founded in 1938 in Bombay by Danish engineers Henning Holck-Larsen and Søren Kristian Toubro. As of 31 March 2022, the L&T Group consisted of 93 subsidiaries, 5 associate companies, 27 joint ventures, and 35 joint operations. As of 1 October 2023, S N Subrahmanyan serves as the chairman and managing director of L&T, having succeeded A M Naik.
B16: Financial Summary
B67: Working Capital/Total Assets
C68: =HistoricalFS!F3 -> 43921 | D68: =HistoricalFS!G3 -> 44286 | E68: =HistoricalFS!H3 -> 44651 | F68: =HistoricalFS!I3 -> 45016 | G68: =HistoricalFS!J3 -> 45382 | H68: =HistoricalFS!K3 -> 45747 | I68: =HistoricalFS!L3 -> 46112
B69: Working Capital | C69: ='Data Sheet'!E65-'Data Sheet'!E60 -> 142884.94 | D69: ='Data Sheet'!F65-'Data Sheet'!F60 -> 126051.27 | E69: ='Data Sheet'!G65-'Data Sheet'!G60 -> 124326 | F69: ='Data Sheet'!H65-'Data Sheet'!H60 -> 119471.51 | G69: ='Data Sheet'!I65-'Data Sheet'!I60 -> 111024.81 | H69: ='Data Sheet'!J65-'Data Sheet'!J60 -> 128615.12 | I69: ='Data Sheet'!K65-'Data Sheet'!K60 -> 132231.74
B70: Total Assets | C70: ='Data Sheet'!E66 -> 306687.09 | D70: ='Data Sheet'!F66 -> 310095.05 | E70: ='Data Sheet'!G66 -> 319027.91 | F70: ='Data Sheet'!H66 -> 329721.88 | G70: ='Data Sheet'!I66 -> 339602.34 | H70: ='Data Sheet'!J66 -> 379114.09 | I70: ='Data Sheet'!K66 -> 452382.77
B71: Working Capital/Total Assets(A) | C71: =C69/C70 -> 0.46589812 | D71: =D69/D70 -> 0.40649236 | E71: =E69/E70 -> 0.38970258 | F71: =F69/F70 -> 0.36234025 | G71: =G69/G70 -> 0.32692593 | H71: =H69/H70 -> 0.33925175 | I71: =I69/I70 -> 0.29230057
B73: Retained Earnings/Total Assets
C74: =C68 -> 43921 | D74: =D68 -> 44286 | E74: =E68 -> 44651 | F74: =F68 -> 45016 | G74: =G68 -> 45382 | H74: =H68 -> 45747 | I74: =I68 -> 46112
B75: Retained Earnings | C75: =HistoricalFS!F36*HistoricalFS!F38*HistoricalFS!F44 -> 5279.83 | D75: =HistoricalFS!G36*HistoricalFS!G38*HistoricalFS!G44 -> 0 | E75: =HistoricalFS!H36*HistoricalFS!H38*HistoricalFS!H44 -> 4835.93 | F75: =HistoricalFS!I36*HistoricalFS!I38*HistoricalFS!I44 -> 6360.97 | G75: =HistoricalFS!J36*HistoricalFS!J38*HistoricalFS!J44 -> 5942.42 | H75: =HistoricalFS!K36*HistoricalFS!K38*HistoricalFS!K44 -> 9813.86 | I75: =HistoricalFS!L36*HistoricalFS!L38*HistoricalFS!L44 -> 8946.13
B76: =B70 -> Total Assets | C76: =C$70 -> 306687.09 | D76: =D$70 -> 310095.05 | E76: =E$70 -> 319027.91 | F76: =F$70 -> 329721.88 | G76: =G$70 -> 339602.34 | H76: =H$70 -> 379114.09 | I76: =I$70 -> 452382.77
B77: Retained Earnings/Total Assets(B) | C77: =C75/C76 -> 0.01721569 | D77: =D75/D76 -> 0 | E77: =E75/E76 -> 0.015158329 | F77: =F75/F76 -> 0.019291926 | G77: =G75/G76 -> 0.017498172 | H77: =H75/H76 -> 0.025886297 | I77: =I75/I76 -> 0.019775576
B79: EBIT/Total Assets
C80: =C74 -> 43921 | D80: =D74 -> 44286 | E80: =E74 -> 44651 | F80: =F74 -> 45016 | G80: =G74 -> 45382 | H80: =H74 -> 45747 | I80: =I74 -> 46112
B81: EBIT | C81: =HistoricalFS!F18-HistoricalFS!F24 -> 22090.83 | D81: =HistoricalFS!G18-HistoricalFS!G24 -> 20556.03 | E81: =HistoricalFS!H18-HistoricalFS!H24 -> 21365.94 | F81: =HistoricalFS!I18-HistoricalFS!I24 -> 23663.77 | G81: =HistoricalFS!J18-HistoricalFS!J24 -> 25075.79 | H81: =HistoricalFS!K18-HistoricalFS!K24 -> 30305.72 | I81: =HistoricalFS!L18-HistoricalFS!L24 -> 31045.95
B82: =B76 -> Total Assets | C82: =C76 -> 306687.09 | D82: =D76 -> 310095.05 | E82: =E76 -> 319027.91 | F82: =F76 -> 329721.88 | G82: =G76 -> 339602.34 | H82: =H76 -> 379114.09 | I82: =I76 -> 452382.77
B83: EBIT/Total Assets(C) | C83: =C81/C82 -> 0.072030518 | D83: =D81/D82 -> 0.066289449 | E83: =E81/E82 -> 0.066972009 | F83: =F81/F82 -> 0.07176888 | G83: =G81/G82 -> 0.073838684 | H83: =H81/H82 -> 0.079938258 | I83: =I81/I82 -> 0.068627614
B85: Market cap/Long Term Liabilities
C86: =C80 -> 43921 | D86: =D80 -> 44286 | E86: =E80 -> 44651 | F86: =F80 -> 45016 | G86: =G80 -> 45382 | H86: =H80 -> 45747 | I86: =I80 -> 46112
B87: Market Cap | C87: =('Data Sheet'!E70*'Data Sheet'!E90)/10000000 -> 113504.67 | D87: =('Data Sheet'!F70*'Data Sheet'!F90)/10000000 -> 199292.35 | E87: =('Data Sheet'!G70*'Data Sheet'!G90)/10000000 -> 248359.97 | F87: =('Data Sheet'!H70*'Data Sheet'!H90)/10000000 -> 304174.46 | G87: =('Data Sheet'!I70*'Data Sheet'!I90)/10000000 -> 517411.52 | H87: =('Data Sheet'!J70*'Data Sheet'!J90)/10000000 -> 480258.36 | I87: =('Data Sheet'!K70*'Data Sheet'!K90)/10000000 -> 482035.28
B88: Long Term Liability | C88: ='Data Sheet'!E59 -> 143173.67 | D88: ='Data Sheet'!F59 -> 134629.08 | E88: ='Data Sheet'!G59 -> 125508.08 | F88: ='Data Sheet'!H59 -> 120650.44 | G88: ='Data Sheet'!I59 -> 116322.22 | H88: ='Data Sheet'!J59 -> 132408.92 | I88: ='Data Sheet'!K59 -> 125496.59
B89: Market cap/Long Term Liabilities(D) | C89: =C87/C88 -> 0.79277614 | D89: =D87/D88 -> 1.4803069 | E89: =E87/E88 -> 1.9788365 | F89: =F87/F88 -> 2.5211218 | G89: =G87/G88 -> 4.4480884 | H89: =H87/H88 -> 3.6270846 | I89: =I87/I88 -> 3.8410229
B93: Sales/Total Assets
C94: =C86 -> 43921 | D94: =D86 -> 44286 | E94: =E86 -> 44651 | F94: =F86 -> 45016 | G94: =G86 -> 45382 | H94: =H86 -> 45747 | I94: =I86 -> 46112
B95: Sales | C95: ='Data Sheet'!E17 -> 145452.36 | D95: ='Data Sheet'!F17 -> 135979.03 | E95: ='Data Sheet'!G17 -> 156521.23 | F95: ='Data Sheet'!H17 -> 183340.7 | G95: ='Data Sheet'!I17 -> 221112.91 | H95: ='Data Sheet'!J17 -> 255734.45 | I95: ='Data Sheet'!K17 -> 285874.36
B96: Total Assets | C96: =C82 -> 306687.09 | D96: =D82 -> 310095.05 | E96: =E82 -> 319027.91 | F96: =F82 -> 329721.88 | G96: =G82 -> 339602.34 | H96: =H82 -> 379114.09 | I96: =I82 -> 452382.77
B97: Sales/Total Assets(E) | C97: =C95/C96 -> 0.47426959 | D97: =D95/D96 -> 0.43850758 | E97: =E95/E96 -> 0.49061924 | F97: =F95/F96 -> 0.55604651 | G97: =G95/G96 -> 0.6510936 | H97: =H95/H96 -> 0.67455802 | I97: =I95/I96 -> 0.63193026
B99: Altman's Z Score
C100: =C94 -> 43921 | D100: =D94 -> 44286 | E100: =E94 -> 44651 | F100: =F94 -> 45016 | G100: =G94 -> 45382 | H100: =H94 -> 45747 | I100: =I94 -> 46112
B101: Final Score | C101: =(C71*1.2)+(C77*1.4)+(C83*3.3)+(C89*0.6)+(C97*1) -> 1.7708157 | D101: =(D71*1.2)+(D77*1.4)+(D83*3.3)+(D89*0.6)+(D97*1) -> 2.0332377 | E101: =(E71*1.2)+(E77*1.4)+(E83*3.3)+(E89*0.6)+(E97*1) -> 2.3877935 | F101: =(F71*1.2)+(F77*1.4)+(F83*3.3)+(F89*0.6)+(F97*1) -> 2.7673739 | G101: =(G71*1.2)+(G77*1.4)+(G83*3.3)+(G89*0.6)+(G97*1) -> 3.9804229 | H101: =(H71*1.2)+(H77*1.4)+(H83*3.3)+(H89*0.6)+(H97*1) -> 3.557948 | I101: =(I71*1.2)+(I77*1.4)+(I83*3.3)+(I89*0.6)+(I97*1) -> 3.5414616
B102: Financial Stability | C102: =IF(C101<1.81,"Distressed",IF(C101>3,"Strong","Grey Zone")) -> Distressed | D102: =IF(D101<1.81,"Distressed",IF(D101>3,"Strong","Grey Zone")) -> Grey Zone | E102: =IF(E101<1.81,"Distressed",IF(E101>3,"Strong","Grey Zone")) -> Grey Zone | F102: =IF(F101<1.81,"Distressed",IF(F101>3,"Strong","Grey Zone")) -> Grey Zone | G102: =IF(G101<1.81,"Distressed",IF(G101>3,"Strong","Grey Zone")) -> Strong | H102: =IF(H101<1.81,"Distressed",IF(H101>3,"Strong","Grey Zone")) -> Strong | I102: =IF(I101<1.81,"Distressed",IF(I101>3,"Strong","Grey Zone")) -> Strong

Sheet DCF>
B2: Calculation of PV of FCFF | E2: ='Intrisic Growth'!I2 -> 46082 | F2: =E2+365 -> 46447 | G2: =F2+365 -> 46812 | H2: =G2+366 -> 47178 | I2: =H2+365 -> 47543 | J2: =I2+365 -> 47908
B4: EBIT | E4: =IFERROR('Data Sheet'!K34-'Data Sheet'!K26,0) -> 32956.34 | F4: =E4*(1+$D$14) -> 39794.781 | G4: =F4*(1+$D$14) -> 48052.198 | H4: =G4*(1+$D$14) -> 58023.028 | I4: =H4*(1+$D$14) -> 70062.807 | J4: =I4*(1+$D$14) -> 84600.839
B5: Tax Rate | E5: 0.25 | F5: =$E$5 -> 0.25 | G5: =$E$5 -> 0.25 | H5: =$E$5 -> 0.25 | I5: =$E$5 -> 0.25 | J5: =$E$5 -> 0.25
B6: EBIT(1-Tax) | E6: =E4*(1-E5) -> 24717.255 | F6: =E6*(1+$D$14) -> 29846.085 | G6: =F6*(1+$D$14) -> 36039.148 | H6: =G6*(1+$D$14) -> 43517.271 | I6: =H6*(1+$D$14) -> 52547.105 | J6: =I6*(1+$D$14) -> 63450.63
B7: Less: Reinvestment Rate | E7: 0.31
B8: Free Cash Flow to Firm(FCFF) | E8: =E6*(1-E7) -> 17054.906 | F8: =E8*(1+$D$14) -> 20593.799 | G8: =F8*(1+$D$14) -> 24867.012 | H8: =G8*(1+$D$14) -> 30026.917 | I8: =H8*(1+$D$14) -> 36257.503 | J8: =I8*(1+$D$14) -> 43780.934
B9: Mid Year Convention | F9: 0.5 | G9: =F9+1 -> 1.5 | H9: =G9+1 -> 2.5 | I9: =H9+1 -> 3.5 | J9: =I9+1 -> 4.5
B10: Discounting Factor | F10: =1/(1+$D$16)^F9 -> 0.944059 | G10: =1/(1+$D$16)^G9 -> 0.84139012 | H10: =1/(1+$D$16)^H9 -> 0.74988676 | I10: =1/(1+$D$16)^I9 -> 0.66833462 | J10: =1/(1+$D$16)^J9 -> 0.59565149
B12: PV of FCFF | F12: =F8*F10 -> 19441.761 | G12: =G8*G10 -> 20922.859 | H12: =H8*H10 -> 22516.788 | I12: =I8*I10 -> 24232.144 | J12: =J8*J10 -> 26078.179
B14: Expected Growth | D14: 0.2075
B15: Terminal Growth | D15: 0.045 | F15: Sensitivity Analysis
B16: WACC | D16: =WACC!J43 -> 0.12202291 | F16: =D37 -> 3203.2351 | G16: 0.12 | H16: 0.122 | I16: 0.135 | J16: 0.14
F17: 0.03 | G17: 2774.6041 | H17: 2719.2986 | I17: 2411.1678 | J17: 2312.0488
B18: Calculation of Terminal Value | F18: 0.04 | G18: 3092.6109 | H18: 3022.8045 | I18: 2640.7065 | J18: 2520.1987
F19: 0.045 | G19: 3283.4149 | H19: 3204.1197 | I19: 2774.6041 | J19: 2640.7065
B20: FCFF(n+1) | D20: =J8*(1+D14) -> 52865.478 | F20: 0.05 | G20: 3501.4767 | H20: 3410.6176 | I20: 2924.2543 | J20: 2774.6041
B21: WACC | D21: =D16 -> 0.12202291 | F21: 0.06 | G21: 4046.6311 | H21: 3923.5318 | I21: 3283.4149 | J21: 3092.6109
B22: Terminal Growth Rate | D22: =D15 -> 0.045 | F22: 0.07 | G22: 4809.8474 | H22: 4633.7206 | I22: 3753.0864 | J22: 3501.4767
B24: Terminal Value | D24: =D20/(D21-D22) -> 686360.4
B26: Calculation of Enterprise Value
B28: PV of FCFF | D28: =SUM(F12:J12) -> 113191.73
B29: PV Terminal Value | D29: =D24*J10 -> 408831.59
B30: Value of Operating Activities | D30: =SUM(D28:D29) -> 522023.32
B32: Add: Cash | D32: ='Data Sheet'!K69 -> 20847.67
B33: Less: debt | D33: =SUM('Raw FS'!N7:N9) -> 102332
B34: Value of Equity | D34: =D30+D32-D33 -> 440538.99
B35: NO. of Shares | D35: ='Data Sheet'!B6 -> 137.5294
B37: Equity Value Per Share | D37: =D34/D35 -> 3203.2351
B39: Share Price | D39: ='Data Sheet'!B8 -> 3785.6
B40: Discount/Premium | D40: =D39/D37-1 -> 0.18180524

Sheet WACC
B2: Weighted Average Cost of Capital
B4: All figures are in INR unless stated otherwise.
B6: Peer Comps
G7: Debt/ | H7: Debt/ | I7: Levered | J7: Unlevered
B8: Name | C8: Country | D8: Total Debt | E8: Total Equity | F8: Tax Rate 1 | G8: Equity | H8: Capital | I8: Beta 2 | J8: Beta 3
B10: ='Beta - Comps'!C4 -> Larsen & Tourbo | C10: India | D10: ='Relative Data'!G3 -> 102332 | E10: ='Beta - Comps'!E4 -> 520631.29 | F10: 0.25 | G10: =D10/E10 -> 0.19655369 | H10: =D10/(D10+E10) -> 0.1642665 | I10: ='Beta - Regression'!J13 -> 1.1623457 | J10: =I10/(1+(1-F10)*G10) -> 1.0130122
B11: ='Beta - Comps'!C5 -> Rail Vikas | C11: India | D11: ='Relative Data'!G4 -> 4818.49 | E11: ='Beta - Comps'!E5 -> 47163.14 | F11: =$F$10 -> 0.25 | G11: =D11/E11 -> 0.10216644 | H11: =D11/(D11+E11) -> 0.092696016 | I11: 1.94 | J11: =I11/(1+(1-F11)*G11) -> 1.8019276
B12: ='Beta - Comps'!C6 -> NBCC | C12: India | D12: ='Relative Data'!G5 -> 0.26 | E12: ='Beta - Comps'!E6 -> 25717.5 | F12: =$F$10 -> 0.25 | G12: =D12/E12 -> 1.0109847e-05 | H12: =D12/(D12+E12) -> 1.0109745e-05 | I12: 1.94 | J12: =I12/(1+(1-F12)*G12) -> 1.9399853
B13: ='Beta - Comps'!C7 -> IRB Infra.Devl. | C13: India | D13: ='Relative Data'!G6 -> 20027.06 | E13: ='Beta - Comps'!E7 -> 23757.42 | F13: =$F$10 -> 0.25 | G13: =D13/E13 -> 0.84298127 | H13: =D13/(D13+E13) -> 0.45740089 | I13: 1.09 | J13: =I13/(1+(1-F13)*G13) -> 0.66779561
B14: ='Beta - Comps'!C8 -> Cemindia Project | C14: India | D14: ='Relative Data'!G7 -> 1001.23 | E14: ='Beta - Comps'!E8 -> 23519.42 | F14: =$F$10 -> 0.25 | G14: =D14/E14 -> 0.042570353 | H14: =D14/(D14+E14) -> 0.040832115 | I14: 1.46 | J14: =I14/(1+(1-F14)*G14) -> 1.4148277
E16: Average | F16: =AVERAGE(F10:F14) -> 0.25 | G16: =AVERAGE(G10:G14) -> 0.23685637 | H16: =AVERAGE(H10:H14) -> 0.15104113 | I16: =AVERAGE(I10:I14) -> 1.5184691 | J16: =AVERAGE(J10:J14) -> 1.3675097
E17: Median | F17: =MEDIAN(F10:F14) -> 0.25 | G17: =MEDIAN(G10:G14) -> 0.10216644 | H17: =MEDIAN(H10:H14) -> 0.092696016 | I17: =MEDIAN(I10:I14) -> 1.46 | J17: =MEDIAN(J10:J14) -> 1.4148277
B20: Cost of Debt | G20: Cost of Equity
B22: Pre-tax Cost of Debt | E22: 0.076 | G22: Risk Free Rate | J22: 0.0685
B23: Tax Rate | E23: =F17 -> 0.25 | G23: Equity Risk Premium | J23: =Rm!G11-WACC!J22 -> 0.056
B24: After Tax Cost of Debt | E24: =E22*(1-E23) -> 0.057 | G24: Levered Beta 4 | J24: ='Beta - Regression'!J13 -> 1.1623457
G25: Cost of Equity | J25: =J22+(J23*J24) -> 0.13359136
B28: Capital Structure | G28: Levered Beta
D30: Current | E30: Target | G30: Comps Median Unlevered Beta | J30: =J17 -> 1.4148277
B31: Total Debt | C31: =D10 -> 102332 | D31: =C31/$C$33 -> 0.1642665 | E31: =H16 -> 0.15104113 | G31: Target Debt/ Equity | J31: =E35 -> 0.17791336
B32: Market Capitalization | C32: =E10 -> 520631.29 | D32: =C32/$C$33 -> 0.8357335 | E32: =E33-E31 -> 0.84895887 | G32: Tax Rate | J32: =E23 -> 0.25
B33: Total Capitalization | C33: =SUM(C31:C32) -> 622963.29 | D33: =C33/$C$33 -> 1 | E33: =D33 -> 1 | G33: Levered Beta | J33: =J30*(1+(1-J31)*J32) -> 1.7056055
B35: Debt / Equity | D35: =D31/D32 -> 0.19655369 | E35: =E31/E32 -> 0.17791336 | G35: Weighted Average Cost of Capital
B37: 1. Tax Rate considered as Marginal Tax Rate for the country | G37: Cost of Equity | J37: =J25 -> 0.13359136
B38: 2. Levered Beta is based on 5 year monthly data | G38: Equity Weight | J38: =E32 -> 0.84895887
B39: 3. Unlevered Beta = Levered Beta/(1+(1-Tax Rate) x Debt/Equity)
B40: 4. Levered Beta = Unlevered Beta/(1+(1-Tax Rate) x Debt/Equity) | G40: Cost of Debt | J40: =E24 -> 0.057
B41: 5.All Beta are calculated on 5 year monthly basis | G41: Debt Weight | J41: =E31 -> 0.15104113
G43: WACC | J43: =(J37*J38)+(J40*J41) -> 0.12202291

Sheet Intrisic Growth
A2: # | B2: Calculation of ROIC | E2: ='Raw FS'!J$2 -> 44621 | F2: ='Raw FS'!K$2 -> 44986 | G2: ='Raw FS'!L$2 -> 45352 | H2: ='Raw FS'!M$2 -> 45717 | I2: ='Raw FS'!N$2 -> 46082
B4: Current Assets
B5: ='Raw FS'!B39 -> Inventories | E5: ='Raw FS'!J39 -> 5943 | F5: ='Raw FS'!K39 -> 6829 | G5: ='Raw FS'!L39 -> 6620 | H5: ='Raw FS'!M39 -> 7671 | I5: ='Raw FS'!N39 -> 9531
B6: ='Raw FS'!B40 -> Trade receivables + | E6: ='Raw FS'!J40 -> 46139 | F6: ='Raw FS'!K40 -> 44732 | G6: ='Raw FS'!L40 -> 48771 | H6: ='Raw FS'!M40 -> 53714 | I6: ='Raw FS'!N40 -> 60461
B7: ='Raw FS'!B42 -> Loans n Advances | E7: ='Raw FS'!J42 -> 41799 | F7: ='Raw FS'!K42 -> 40356 | G7: ='Raw FS'!L42 -> 34700 | H7: ='Raw FS'!M42 -> 34244 | I7: ='Raw FS'!N42 -> 40747
B8: ='Raw FS'!B43 -> Other asset items | E8: ='Raw FS'!J43 -> 122604 | F8: ='Raw FS'!K43 -> 124781 | G8: ='Raw FS'!L43 -> 142496 | H8: ='Raw FS'!M43 -> 159071 | I8: ='Raw FS'!N43 -> 218241
B9: Total Current Assets | E9: =SUM(E5:E8) -> 216485 | F9: =SUM(F5:F8) -> 216698 | G9: =SUM(G5:G8) -> 232587 | H9: =SUM(H5:H8) -> 254700 | I9: =SUM(I5:I8) -> 328980
B11: Current Liabilities
B12: ='Raw FS'!B14 -> Trade Payables | E12: ='Raw FS'!J14 -> 51366 | F12: ='Raw FS'!K14 -> 49784 | G12: ='Raw FS'!L14 -> 53293 | H12: ='Raw FS'!M14 -> 52459 | I12: ='Raw FS'!N14 -> 69456
B13: ='Raw FS'!B15 -> Advance from Customers | E13: ='Raw FS'!J15 -> 17963 | F13: ='Raw FS'!K15 -> 20425 | G13: ='Raw FS'!L15 -> 26875 | H13: ='Raw FS'!M15 -> 29087 | I13: ='Raw FS'!N15 -> 39586
B14: ='Raw FS'!B16 -> Other liability items | E14: ='Raw FS'!J16 -> 28817 | F14: ='Raw FS'!K16 -> 35297 | G14: ='Raw FS'!L16 -> 40562 | H14: ='Raw FS'!M16 -> 49755 | I14: ='Raw FS'!N16 -> 89312
B15: Total Current Liabilities | E15: =SUM(E12:E14) -> 98146 | F15: =SUM(F12:F14) -> 105506 | G15: =SUM(G12:G14) -> 120730 | H15: =SUM(H12:H14) -> 131301 | I15: =SUM(I12:I14) -> 198354
A17: # | B17: Net Working Capital | E17: =E9-E15 -> 118339 | F17: =F9-F15 -> 111192 | G17: =G9-G15 -> 111857 | H17: =H9-H15 -> 123399 | I17: =I9-I15 -> 130626
B19: Non Current Assets
B20: ='Raw FS'!B20 -> Land | E20: ='Raw FS'!J20 -> 1347 | F20: ='Raw FS'!K20 -> 1436 | G20: ='Raw FS'!L20 -> 1000 | H20: ='Raw FS'!M20 -> 1703 | I20: ='Raw FS'!N20 -> 1803
B21: ='Raw FS'!B21 -> Building | E21: ='Raw FS'!J21 -> 6745 | F21: ='Raw FS'!K21 -> 6998 | G21: ='Raw FS'!L21 -> 6680 | H21: ='Raw FS'!M21 -> 9951 | I21: ='Raw FS'!N21 -> 11326
B22: ='Raw FS'!B22 -> Plant Machinery | E22: ='Raw FS'!J22 -> 9298 | F22: ='Raw FS'!K22 -> 10859 | G22: ='Raw FS'!L22 -> 12570 | H22: ='Raw FS'!M22 -> 14870 | I22: ='Raw FS'!N22 -> 15800
B23: ='Raw FS'!B23 -> Ships Vessels | E23: ='Raw FS'!J23 -> 947 | F23: ='Raw FS'!K23 -> 969 | G23: ='Raw FS'!L23 -> 1007 | H23: ='Raw FS'!M23 -> 1025 | I23: ='Raw FS'!N23 -> 1696
B24: ='Raw FS'!B24 -> Equipments | E24: ='Raw FS'!J24 -> 630 | F24: ='Raw FS'!K24 -> 716 | G24: ='Raw FS'!L24 -> 762 | H24: ='Raw FS'!M24 -> 871 | I24: ='Raw FS'!N24 -> 1060
B25: ='Raw FS'!B25 -> Computers | E25: ='Raw FS'!J25 -> 2067 | F25: ='Raw FS'!K25 -> 2448 | G25: ='Raw FS'!L25 -> 2572 | H25: ='Raw FS'!M25 -> 2803 | I25: ='Raw FS'!N25 -> 3152
B26: ='Raw FS'!B26 -> Furniture n fittings | E26: ='Raw FS'!J26 -> 499 | F26: ='Raw FS'!K26 -> 508 | G26: ='Raw FS'!L26 -> 633 | H26: ='Raw FS'!M26 -> 672 | I26: ='Raw FS'!N26 -> 754
B27: ='Raw FS'!B27 -> Railway sidings | E27: ='Raw FS'!J27 -> 0 | F27: ='Raw FS'!K27 -> 0 | G27: ='Raw FS'!L27 -> 0 | H27: ='Raw FS'!M27 -> 0 | I27: ='Raw FS'!N27 -> 0
B28: ='Raw FS'!B28 -> Vehicles | E28: ='Raw FS'!J28 -> 650 | F28: ='Raw FS'!K28 -> 652 | G28: ='Raw FS'!L28 -> 657 | H28: ='Raw FS'!M28 -> 768 | I28: ='Raw FS'!N28 -> 1380
B29: ='Raw FS'!B29 -> Intangible Assets | E29: ='Raw FS'!J29 -> 24950 | F29: ='Raw FS'!K29 -> 25099 | G29: ='Raw FS'!L29 -> 24837 | H29: ='Raw FS'!M29 -> 25860 | I29: ='Raw FS'!N29 -> 9432
B30: ='Raw FS'!B30 -> Other fixed assets | E30: ='Raw FS'!J30 -> 9361 | F30: ='Raw FS'!K30 -> 9071 | G30: ='Raw FS'!L30 -> 10408 | H30: ='Raw FS'!M30 -> 7867 | I30: ='Raw FS'!N30 -> 7487
B32: Gross Block | E32: =SUM(E20:E31) -> 56494 | F32: =SUM(F20:F31) -> 58756 | G32: =SUM(G20:G31) -> 61126 | H32: =SUM(H20:H31) -> 66390 | I32: =SUM(I20:I31) -> 53890
B33: ='Raw FS'!B32 -> Accumulated Depreciation | E33: =-('Raw FS'!J32) -> -13550 | F33: =-('Raw FS'!K32) -> -16115 | G33: =-('Raw FS'!L32) -> -18161 | H33: =-('Raw FS'!M32) -> -22334 | I33: =-('Raw FS'!N32) -> -23023
A34: # | B34: Net Non Current Assets | E34: =SUM(E32:E33) -> 42944 | F34: =SUM(F32:F33) -> 42641 | G34: =SUM(G32:G33) -> 42965 | H34: =SUM(H32:H33) -> 44056 | I34: =SUM(I32:I33) -> 30867
A36: # | B36: Invested Capital | E36: =E34+E17 -> 161283 | F36: =F34+F17 -> 153833 | G36: =G34+G17 -> 154822 | H36: =H34+H17 -> 167455 | I36: =I34+I17 -> 161493
B37: EBIT | E37: =(HistoricalFS!H27+HistoricalFS!H21) -> 21365.94 | F37: =(HistoricalFS!I27+HistoricalFS!I21) -> 23663.77 | G37: =(HistoricalFS!J27+HistoricalFS!J21) -> 25075.79 | H37: =(HistoricalFS!K27+HistoricalFS!K21) -> 30305.72 | I37: =(HistoricalFS!L27+HistoricalFS!L21) -> 31045.95
A39: # | B39: ROIC | E39: =E37/E36 -> 0.13247484 | F39: =F37/F36 -> 0.15382766 | G39: =G37/G36 -> 0.16196529 | H39: =H37/H36 -> 0.18097829 | I39: =I37/I36 -> 0.19224332
A42: # | B42: Calculation of Reinvestment Rate | E42: ='Raw FS'!J$2 -> 44621 | F42: ='Raw FS'!K$2 -> 44986 | G42: ='Raw FS'!L$2 -> 45352 | H42: ='Raw FS'!M$2 -> 45717 | I42: ='Raw FS'!N$2 -> 46082
B44: Net Capex | E44: =-SUM(CFS!I12:I13) -> 3040 | F44: =-SUM(CFS!J12:J13) -> 3794 | G44: =-SUM(CFS!K12:K13) -> 4211 | H44: =-SUM(CFS!L12:L13) -> 3541 | I44: =-SUM(CFS!M12:M13) -> 4468
B45: Change in Working Capital | F45: =F17-E17 -> -7147 | G45: =G17-F17 -> 665 | H45: =H17-G17 -> 11542 | I45: =I17-H17 -> 7227
B47: EBIT | E47: =E37 -> 21365.94 | F47: =F37 -> 23663.77 | G47: =G37 -> 25075.79 | H47: =H37 -> 30305.72 | I47: =I37 -> 31045.95
B48: Marginal Tax Rate | E48: ='Data Sheet'!G32 -> 0.29002613 | F48: ='Data Sheet'!H32 -> 0.26209318 | G48: ='Data Sheet'!I32 -> 0.24113484 | H48: ='Data Sheet'!J32 -> 0.24986015 | I48: ='Data Sheet'!K32 -> 0.26241376
B49: EBIT(1-T) | E49: =E47*(1-E48) -> 15169.259 | F49: =F47*(1-F48) -> 17461.657 | G49: =G47*(1-G48) -> 19029.143 | H49: =H47*(1-H48) -> 22733.528 | I49: =I47*(1-I48) -> 22899.065
B51: Reinvestment | F51: =SUM(F44:F45) -> -3353 | G51: =SUM(G44:G45) -> 4876 | H51: =SUM(H44:H45) -> 15083 | I51: =SUM(I44:I45) -> 11695
B53: Reinvestment Rate | F53: =F51/F49 -> -0.19202072 | G53: =G51/G49 -> 0.25623854 | H53: =H51/H49 -> 0.66346938 | I53: =I51/I49 -> 0.51071953
H55: 4 Year Average | I55: =AVERAGE(F53:I53) -> 0.30960169
...

Sheet Beta - Regression
E2: needs correction
B3: Regression Beta - 5 Years Monthly
B5: ='Data Sheet'!B1 &" - " & "Weekly Returns" -> LARSEN & TOUBRO LTD - Weekly Returns | F5: NIFTY Returns | I5: Beta Drifting | L5: Beta 1 | M5: =SLOPE(D8:D66,G8:G66) -> 1.2164609
B6: Date | C6: Closing Price | D6: Return | F6: Closing Price | G6: Return | L6: Beta 2 | M6: =_xlfn.COVARIANCE.S(D7:D66,G7:G66)/VAR(G7:G66) -> 1.2164609
B7: 46029 | C7: 3937.7 | F7: 23979.6 | I7: Levered Raw Beta | J7: =M5 -> 1.2164609
B8: 46028 | C8: 4143.4 | D8: =C8/C7-1 -> 0.052238616 | F8: 23865.75 | G8: =F8/F7-1 -> -0.0047477856 | I8: Raw Beta Weight | J8: 0.75
B9: 46027 | C9: 4076.5 | D9: =C9/C8-1 -> -0.01614616 | F9: 23547.75 | G9: =F9/F8-1 -> -0.013324534
B10: 46026 | C10: 4014 | D10: =C10/C9-1 -> -0.01533178 | F10: 23997.55 | G10: =F10/F9-1 -> 0.019101613 | I10: Market Beta | J10: 1
B11: 46025 | C11: 3504.1 | D11: =C11/C10-1 -> -0.12703039 | F11: 22331.4 | G11: =F11/F10-1 -> -0.069430004 | I11: Market Beta Weight | J11: 0.25
B12: 46024 | C12: 4278.3 | D12: =C12/C11-1 -> 0.22094118 | F12: 25178.65 | G12: =F12/F11-1 -> 0.12749984
B13: 46023 | C13: 3932.3 | D13: =C13/C12-1 -> -0.080873244 | F13: 25320.65 | G13: =F13/F12-1 -> 0.0056396987 | I13: Adjusted Beta | J13: =(J7*J8)+(J10*J11) -> 1.1623457
B14: 45669 | C14: 4083.5 | D14: =C14/C13-1 -> 0.038450779 | F14: 26129.6 | G14: =F14/F13-1 -> 0.031948232
B15: 45668 | C15: 4069.6 | D15: =C15/C14-1 -> -0.0034039427 | F15: 26202.95 | G15: =F15/F14-1 -> 0.0028071612
B16: 45667 | C16: 4030.9 | D16: =C16/C15-1 -> -0.0095095341 | F16: 25722.1 | G16: =F16/F15-1 -> -0.018350987
B17: 45666 | C17: 3659 | D17: =C17/C16-1 -> -0.092262274 | F17: 24611.1 | G17: =F17/F16-1 -> -0.04319243
B18: 45665 | C18: 3601 | D18: =C18/C17-1 -> -0.015851325 | F18: 24426.85 | G18: =F18/F17-1 -> -0.0074864594
B19: 45664 | C19: 3636.5 | D19: =C19/C18-1 -> 0.0098583727 | F19: 24768.35 | G19: =F19/F18-1 -> 0.013980517
B20: 45663 | C20: 3669.8 | D20: =C20/C19-1 -> 0.0091571566 | F20: 25517.05 | G20: =F20/F19-1 -> 0.030228094
B21: 45662 | C21: 3675.1 | D21: =C21/C20-1 -> 0.0014442204 | F21: 24750.7 | G21: =F21/F20-1 -> -0.03003286
B22: 45661 | C22: 3341 | D22: =C22/C21-1 -> -0.090909091 | F22: 24334.2 | G22: =F22/F21-1 -> -0.016827807
B23: 45660 | C23: 3492.3 | D23: =C23/C22-1 -> 0.045285843 | F23: 23519.35 | G23: =F23/F22-1 -> -0.033485794
B24: 45659 | C24: 3163.85 | D24: =C24/C23-1 -> -0.094049767 | F24: 22124.7 | G24: =F24/F23-1 -> -0.059297982
B25: 45658 | C25: 3567.4 | D25: =C25/C24-1 -> 0.12755029 | F25: 23508.4 | G25: =F25/F24-1 -> 0.062540961
... B66: 44204 | C66: 1668.44 | D66: =C66/C65-1 -> -0.018056406 | F66: 17132.2 | G66: =F66/F65-1 -> -0.027582351

Sheet Relative valuation
B3: Amount in crores
B4: Comparable Company Valuations
D6: Market Data | K6: Financials | O6: Valuation
B7: Company | C7: Ticker | D7: Share prize | E7: Shares Outstanding | F7: Equity Value | G7: Net Debt | H7: Enterprise Value | K7: Revenue | L7: EBITDA | M7: Net Income | O7: EV/Revenue | P7: EV/EBITDA | Q7: P/E
B9: ='Beta - Comps'!C4 -> Larsen & Tourbo | D9: ='Relative Data'!D3 -> 3785.6 | E9: ='Relative Data'!E3 -> 137.5294 | F9: =E9*D9 -> 520631.29 | G9: ='Relative Data'!I3 -> 81484.33 | H9: =G9+F9 -> 602115.62 | K9: ='Data Sheet'!K17 -> 285874.36 | L9: ='Relative Data'!L3 -> 37321.09 | M9: ='Relative Data'!M3 -> 16083.99 | O9: ='Relative Data'!J3/'Relative Data'!K3 -> 2.1062246 | P9: ='Relative Data'!$J3/'Relative valuation'!L9 -> 16.133388 | Q9: ='Relative Data'!O3 -> 32.369536
B10: ='Beta - Comps'!C5 -> Rail Vikas | D10: ='Beta - Comps'!D5 -> 226.2 | E10: ='Relative Data'!E4 -> 208.50195 | F10: =E10*D10 -> 47163.14 | G10: ='Relative Data'!I4 -> 3850.24 | H10: =G10+F10 -> 51013.38 | K10: ='Relative Data'!K4 -> 20412.12 | L10: ='Relative Data'!L4 -> 1636.6179 | M10: ='Relative Data'!M4 -> 875.01187 | O10: ='Relative Data'!$J4/'Relative valuation'!K10 -> 2.4991711 | P10: ='Relative Data'!$J4/'Relative valuation'!L10 -> 31.17 | Q10: ='Relative Data'!O4 -> 53.9
B11: ='Beta - Comps'!C6 -> NBCC | D11: ='Beta - Comps'!D6 -> 95.25 | E11: ='Relative Data'!E5 -> 270 | F11: =E11*D11 -> 25717.5 | G11: ='Relative Data'!I5 -> -6515.36 | H11: =G11+F11 -> 19202.14 | K11: ='Relative Data'!K5 -> 12888.61 | L11: ='Relative Data'!L5 -> 924.06833 | M11: ='Relative Data'!M5 -> 661.96911 | O11: ='Relative Data'!$J5/'Relative valuation'!K11 -> 1.4898534 | P11: ='Relative Data'!$J5/'Relative valuation'!L11 -> 20.78 | Q11: ='Relative Data'!O5 -> 38.85
B12: ='Beta - Comps'!C7 -> IRB Infra.Devl. | D12: ='Beta - Comps'!D7 -> 19.67 | E12: ='Relative Data'!E6 -> 1207.7997 | F12: =E12*D12 -> 23757.42 | G12: ='Relative Data'!I6 -> 18116.1 | H12: =G12+F12 -> 41873.52 | K12: ='Relative Data'!K6 -> 7648.15 | L12: ='Relative Data'!L6 -> 2476.2578 | M12: ='Relative Data'!M6 -> 879.25315 | O12: ='Relative Data'!$J6/'Relative valuation'!K12 -> 5.4749868 | P12: ='Relative Data'!$J6/'Relative valuation'!L12 -> 16.91 | Q12: ='Relative Data'!O6 -> 27.02
B13: ='Beta - Comps'!C8 -> Cemindia Project | D13: ='Beta - Comps'!D8 -> 1369.1 | E13: ='Relative Data'!E7 -> 17.178745 | F13: =E13*D13 -> 23519.42 | G13: ='Relative Data'!I7 -> 52.38 | H13: =G13+F13 -> 23571.8 | K13: ='Relative Data'!K7 -> 10060.58 | L13: ='Relative Data'!L7 -> 1393.9562 | M13: ='Relative Data'!M7 -> 588.42682 | O13: ='Relative Data'!$J7/'Relative valuation'!K13 -> 2.3429862 | P13: ='Relative Data'!$J7/'Relative valuation'!L13 -> 16.91 | Q13: ='Relative Data'!O7 -> 39.97
B15: High | O15: =MAX(O9:O13) -> 5.4749868 | P15: =MAX(P9:P13) -> 31.17 | Q15: =MAX(Q9:Q13) -> 53.9
B16: 75th Percentile | O16: =QUARTILE(O9:O13,3) -> 2.4991711 | P16: =QUARTILE(P9:P13,3) -> 20.78 | Q16: =QUARTILE(Q9:Q13,3) -> 39.97
B17: Average | O17: =AVERAGE(O9:O13) -> 2.7826444 | P17: =AVERAGE(P9:P13) -> 20.380678 | Q17: =AVERAGE(Q9:Q13) -> 38.421907
B18: Median | O18: =MEDIAN(O9:O13) -> 2.3429862 | P18: =MEDIAN(P9:P13) -> 16.91 | Q18: =MEDIAN(Q9:Q13) -> 38.85
B19: 25th Percentile | O19: =QUARTILE(O9:O13,1) -> 2.1062246 | P19: =QUARTILE(P9:P13,1) -> 16.91 | Q19: =QUARTILE(Q9:Q13,1) -> 32.369536
B20: Low | O20: =MIN(O9:O13) -> 1.4898534 | P20: =MIN(P9:P13) -> 16.133388 | Q20: =MIN(Q9:Q13) -> 27.02
B22: Comparable Company Valuations | O22: EV/Revenue | P22: EV/EBITDA | Q22: P/E
B24: Implied Enterprise Value | O24: =O18*K9 -> 669799.68 | P24: =P18*L9 -> 631099.63 | Q24: =Q26+Q25 -> 706347.34
B25: Net Debt | O25: =$G$9 -> 81484.33 | P25: =$G$9 -> 81484.33 | Q25: =$G$9 -> 81484.33
B26: Implied Market Value | O26: =O24-O25 -> 588315.35 | P26: =P24-P25 -> 549615.3 | Q26: =Q18*M9 -> 624863.01
B27: Shares Outstanding | O27: =$E$9 -> 137.5294 | P27: =$E$9 -> 137.5294 | Q27: =$E$9 -> 137.5294
B29: Implied value per share | O29: =O26/O27 -> 4277.7425 | P29: =P26/P27 -> 3996.3478 | Q29: =Q26/Q27 -> 4543.4868
B31: Source: The Valuation School, Screener.in
O32: =IF(O29>$D$8,"Undervalued","Overvalued") -> Undervalued | P32: =IF(P29>$D$8,"Undervalued","Overvalued") -> Undervalued | Q32: =IF(Q29>$D$8,"Undervalued","Overvalued") -> Undervalued

Sheet Beta - Comps
B3: S.No. | C3: Name | D3: CMP Rs. | E3: Mar Cap Rs.Cr. | F3: Debt Rs.Cr. | G3: Debt / Eq
B4: 1 | C4: ='Relative Data'!C3 -> Larsen & Tourbo | D4: ='Relative Data'!D3 -> 3785.6 | E4: ='Relative Data'!F3 -> 520631.29 | F4: ='Relative Data'!G3 -> 102332 | G4: ='Beta - Comps'!F4/'Beta - Comps'!E4 -> 0.19655369
B5: 2 | C5: ='Relative Data'!C4 -> Rail Vikas | D5: ='Relative Data'!D4 -> 226.2 | E5: ='Relative Data'!F4 -> 47163.14 | F5: ='Relative Data'!G4 -> 4818.49 | G5: ='Beta - Comps'!F5/'Beta - Comps'!E5 -> 0.10216644
B6: 3 | C6: ='Relative Data'!C5 -> NBCC | D6: ='Relative Data'!D5 -> 95.25 | E6: ='Relative Data'!F5 -> 25717.5 | F6: ='Relative Data'!G5 -> 0.26 | G6: ='Beta - Comps'!F6/'Beta - Comps'!E6 -> 1.0109847e-05
B7: 4 | C7: ='Relative Data'!C6 -> IRB Infra.Devl. | D7: ='Relative Data'!D6 -> 19.67 | E7: ='Relative Data'!F6 -> 23757.42 | F7: ='Relative Data'!G6 -> 20027.06 | G7: ='Beta - Comps'!F7/'Beta - Comps'!E7 -> 0.84298127
B8: 5 | C8: ='Relative Data'!C7 -> Cemindia Project | D8: ='Relative Data'!D7 -> 1369.1 | E8: ='Relative Data'!F7 -> 23519.42 | F8: ='Relative Data'!G7 -> 1001.23 | G8: ='Beta - Comps'!F8/'Beta - Comps'!E8 -> 0.042570353

Sheet Rm
B6: Return on Markets - Nifty 50
B8: Year | C8: Annual
B9: 2011 | C9: -0.2462 | E9: Average Return | G9: =AVERAGE(C9:C23) -> 0.1106
B10: 2012 | C10: 0.277 | E10: Dividend Yield | G10: 0.0139
B11: 2013 | C11: 0.0676 | E11: Total Market Returns | G11: =SUM(G10,G9) -> 0.1245
B12: 2014 | C12: 0.3139
B13: 2015 | C13: -0.0406
B14: 2016 | C14: 0.0301
B15: 2017 | C15: 0.2865
B16: 2018 | C16: 0.0315
B17: 2019 | C17: 0.1202
B18: 2020 | C18: 0.1417
B19: 2021 | C19: 0.2412
B20: 2022 | C20: 0.0432
B21: 2023 | C21: 0.2003
B22: 2024 | C22: 0.0876
B23: 2025 | C23: 0.105

Sheet Analysis
B3: ='Data Sheet'!B1 -> LARSEN & TOUBRO LTD
B4: =CONCATENATE("(",_xlfn.XLOOKUP(B3,'List Of Stocks'!B2:B5442,'List Of Stocks'!D2:D5442), " | ","BSE Code: ",_xlfn.XLOOKUP(Analysis!B3,'List Of Stocks'!B2:B5442,'List Of Stocks'!C2:C5442,,0)," ) ") -> (LT | BSE Code: 500510 )
B5: =CONCATENATE("INR", " ",'Data Sheet'!B8) -> INR 3785.6
B6: ="52 Week" & " "&"("&"High -" & " INR " &'Football Field Analysis'!Q10 & " " &"LOW - " & " INR " &'Football Field Analysis'!N10 &")" -> 52 Week (High - INR 4440 LOW - INR 3288)
B8: About The Company
B9: Larsen & Toubro Limited (L&T) is an Indian multinational conglomerate headquartered in Mumbai. It operates in sectors including industrial technology, heavy industry, engineering, construction, manufacturing, power, information technology, defence, and financial services. L&T was founded in 1938 in Bombay by Danish engineers Henning Holck-Larsen and Søren Kristian Toubro. As of 31 March 2022, the L&T Group consisted of 93 subsidiaries, 5 associate companies, 27 joint ventures, and 35 joint operations. As of 1 October 2023, S N Subrahmanyan serves as the chairman and managing director of L&T, having succeeded A M Naik.
B17: Financial Summary
B68: Return On Equity(ROE)
C69: =HistoricalFS!F3 -> 43921 | D69: =HistoricalFS!G3 -> 44286 | E69: =HistoricalFS!H3 -> 44651 | F69: =HistoricalFS!I3 -> 45016 | G69: =HistoricalFS!J3 -> 45382 | H69: =HistoricalFS!K3 -> 45747 | I69: =HistoricalFS!L3 -> 46112
B70: Net Profit | C70: =IFERROR('Data Sheet'!E30,0) -> 9549.03 | D70: =IFERROR('Data Sheet'!F30,0) -> 11582.93 | E70: =IFERROR('Data Sheet'!G30,0) -> 8669.33 | F70: =IFERROR('Data Sheet'!H30,0) -> 10470.72 | G70: =IFERROR('Data Sheet'!I30,0) -> 13059.11 | H70: =IFERROR('Data Sheet'!J30,0) -> 15037.11 | I70: =IFERROR('Data Sheet'!K30,0) -> 16083.99
B71: Average Shareholder Equity | C71: =IFERROR((('Data Sheet'!E57+'Data Sheet'!E58)+('Data Sheet'!D58+'Data Sheet'!D57))/2,0) -> 64549.01 | D71: =IFERROR((('Data Sheet'!F57+'Data Sheet'!F58)+('Data Sheet'!E58+'Data Sheet'!E57))/2,0) -> 71295.875 | E71: =IFERROR((('Data Sheet'!G57+'Data Sheet'!G58)+('Data Sheet'!F58+'Data Sheet'!F57))/2,0) -> 79138.095 | F71: =IFERROR((('Data Sheet'!H57+'Data Sheet'!H58)+('Data Sheet'!G58+'Data Sheet'!G57))/2,0) -> 85866.805 | G71: =IFERROR((('Data Sheet'!I57+'Data Sheet'!I58)+('Data Sheet'!H58+'Data Sheet'!H57))/2,0) -> 87842.595 | H71: =IFERROR((('Data Sheet'!J57+'Data Sheet'!J58)+('Data Sheet'!I58+'Data Sheet'!I57))/2,0) -> 92007.42 | I71: =IFERROR((('Data Sheet'!K57+'Data Sheet'!K58)+('Data Sheet'!J58+'Data Sheet'!J57))/2,0) -> 103472.7
B72: Return On Equity | C72: =C70/C71 -> 0.14793457 | D72: =D70/D71 -> 0.16246284 | E72: =E70/E71 -> 0.10954686 | F72: =F70/F71 -> 0.12194142 | G72: =G70/G71 -> 0.14866489 | H72: =H70/H71 -> 0.16343367 | I72: =I70/I71 -> 0.15544187
B74: ROE - Dupont Equation
C75: =C69 -> 43921 | D75: =D69 -> 44286 | E75: =E69 -> 44651 | F75: =F69 -> 45016 | G75: =G69 -> 45382 | H75: =H69 -> 45747 | I75: =I69 -> 46112
B76: =B70 -> Net Profit | C76: =C70 -> 9549.03 | D76: =D70 -> 11582.93 | E76: =E70 -> 8669.33 | F76: =F70 -> 10470.72 | G76: =G70 -> 13059.11 | H76: =H70 -> 15037.11 | I76: =I70 -> 16083.99
B77: Revenue | C77: =IFERROR('Data Sheet'!E17,0) -> 145452.36 | D77: =IFERROR('Data Sheet'!F17,0) -> 135979.03 | E77: =IFERROR('Data Sheet'!G17,0) -> 156521.23 | F77: =IFERROR('Data Sheet'!H17,0) -> 183340.7 | G77: =IFERROR('Data Sheet'!I17,0) -> 221112.91 | H77: =IFERROR('Data Sheet'!J17,0) -> 255734.45 | I77: =IFERROR('Data Sheet'!K17,0) -> 285874.36
B78: Net Profit Margin(A) | C78: =C76/C77 -> 0.065650568 | D78: =D76/D77 -> 0.085181737 | E78: =E76/E77 -> 0.055387566 | F78: =F76/F77 -> 0.057110723 | G78: =G76/G77 -> 0.059060821 | H78: =H76/H77 -> 0.058799704 | I78: =I76/I77 -> 0.056262443
C80: =C75 -> 43921 | D80: =D75 -> 44286 | E80: =E75 -> 44651 | F80: =F75 -> 45016 | G80: =G75 -> 45382 | H80: =H75 -> 45747 | I80: =I75 -> 46112
B81: Revenue | C81: =C77 -> 145452.36 | D81: =D77 -> 135979.03 | E81: =E77 -> 156521.23 | F81: =F77 -> 183340.7 | G81: =G77 -> 221112.91 | H81: =H77 -> 255734.45 | I81: =I77 -> 285874.36
B82: Average Total Assets | C82: =IFERROR(('Data Sheet'!E66+'Data Sheet'!D66)/2,0) -> 292361.66 | D82: =IFERROR(('Data Sheet'!F66+'Data Sheet'!E66)/2,0) -> 308391.07 | E82: =IFERROR(('Data Sheet'!G66+'Data Sheet'!F66)/2,0) -> 314561.48 | F82: =IFERROR(('Data Sheet'!H66+'Data Sheet'!G66)/2,0) -> 324374.9 | G82: =IFERROR(('Data Sheet'!I66+'Data Sheet'!H66)/2,0) -> 334662.11 | H82: =IFERROR(('Data Sheet'!J66+'Data Sheet'!I66)/2,0) -> 359358.22 | I82: =IFERROR(('Data Sheet'!K66+'Data Sheet'!J66)/2,0) -> 415748.43
B83: Asset Turnover Ratio(B) | C83: =C81/C82 -> 0.49750833 | D83: =D81/D82 -> 0.4409305 | E83: =E81/E82 -> 0.4975855 | F83: =F81/F82 -> 0.56521236 | G83: =G81/G82 -> 0.66070494 | H83: =H81/H82 -> 0.71164214 | I83: =I81/I82 -> 0.68761381
C85: =C80 -> 43921 | D85: =D80 -> 44286 | E85: =E80 -> 44651 | F85: =F80 -> 45016 | G85: =G80 -> 45382 | H85: =H80 -> 45747 | I85: =I80 -> 46112
B86: Average Total Assets | C86: =IFERROR(('Data Sheet'!E66+'Data Sheet'!D66)/2,0) -> 292361.66 | D86: =IFERROR(('Data Sheet'!F66+'Data Sheet'!E66)/2,0) -> 308391.07 | E86: =IFERROR(('Data Sheet'!G66+'Data Sheet'!F66)/2,0) -> 314561.48 | F86: =IFERROR(('Data Sheet'!H66+'Data Sheet'!G66)/2,0) -> 324374.9 | G86: =IFERROR(('Data Sheet'!I66+'Data Sheet'!H66)/2,0) -> 334662.11 | H86: =IFERROR(('Data Sheet'!J66+'Data Sheet'!I66)/2,0) -> 359358.22 | I86: =IFERROR(('Data Sheet'!K66+'Data Sheet'!J66)/2,0) -> 415748.43
B87: Average Shareholder Equity | C87: =IFERROR((('Data Sheet'!E57+'Data Sheet'!E58)+('Data Sheet'!D58+'Data Sheet'!D57))/2,0) -> 64549.01 | D87: =IFERROR((('Data Sheet'!F57+'Data Sheet'!F58)+('Data Sheet'!E58+'Data Sheet'!E57))/2,0) -> 71295.875 | E87: =IFERROR((('Data Sheet'!G57+'Data Sheet'!G58)+('Data Sheet'!F58+'Data Sheet'!F57))/2,0) -> 79138.095 | F87: =IFERROR((('Data Sheet'!H57+'Data Sheet'!H58)+('Data Sheet'!G58+'Data Sheet'!G57))/2,0) -> 85866.805 | G87: =IFERROR((('Data Sheet'!I57+'Data Sheet'!I58)+('Data Sheet'!H58+'Data Sheet'!H57))/2,0) -> 87842.595 | H87: =IFERROR((('Data Sheet'!J57+'Data Sheet'!J58)+('Data Sheet'!I58+'Data Sheet'!I57))/2,0) -> 92007.42 | I87: =IFERROR((('Data Sheet'!K57+'Data Sheet'!K58)+('Data Sheet'!J58+'Data Sheet'!J57))/2,0) -> 103472.7
B88: Financial Leverage(C) | C88: =C86/C87 -> 4.5292974 | D88: =D86/D87 -> 4.3255107 | E88: =E86/E87 -> 3.9748427 | F88: =F86/F87 -> 3.7776519 | G88: =G86/G87 -> 3.8097931 | H88: =H86/H87 -> 3.9057525 | I88: =I86/I87 -> 4.0179529
B90: Return On Equity(A*B*C) | C90: =C88*C83*C78 -> 0.14793457 | D90: =D88*D83*D78 -> 0.16246284 | E90: =E88*E83*E78 -> 0.10954686 | F90: =F88*F83*F78 -> 0.12194142 | G90: =G88*G83*G78 -> 0.14866489 | H90: =H88*H83*H78 -> 0.16343367 | I90: =I88*I83*I78 -> 0.15544187
B92: Return On Asset(ROA)
C93: =C85 -> 43921 | D93: =D85 -> 44286 | E93: =E85 -> 44651 | F93: =F85 -> 45016 | G93: =G85 -> 45382 | H93: =H85 -> 45747 | I93: =I85 -> 46112
B94: Net Profit | C94: =C76 -> 9549.03 | D94: =D76 -> 11582.93 | E94: =E76 -> 8669.33 | F94: =F76 -> 10470.72 | G94: =G76 -> 13059.11 | H94: =H76 -> 15037.11 | I94: =I76 -> 16083.99
B95: =B86 -> Average Total Assets | C95: =C86 -> 292361.66 | D95: =D86 -> 308391.07 | E95: =E86 -> 314561.48 | F95: =F86 -> 324374.9 | G95: =G86 -> 334662.11 | H95: =H86 -> 359358.22 | I95: =I86 -> 415748.43
B96: Return On Asset | C96: =C94/C95 -> 0.032661704 | D96: =D94/D95 -> 0.037559226 | E96: =E94/E95 -> 0.02756005 | F96: =F94/F95 -> 0.032279687 | G96: =G94/G95 -> 0.039021776 | H96: =H94/H95 -> 0.041844347 | I96: =I94/I95 -> 0.038686833
B98: ROA - Dupont Analysis
C99: =C93 -> 43921 | D99: =D93 -> 44286 | E99: =E93 -> 44651 | F99: =F93 -> 45016 | G99: =G93 -> 45382 | H99: =H93 -> 45747 | I99: =I93 -> 46112
B100: Net Profit | C100: =C94 -> 9549.03 | D100: =D94 -> 11582.93 | E100: =E94 -> 8669.33 | F100: =F94 -> 10470.72 | G100: =G94 -> 13059.11 | H100: =H94 -> 15037.11 | I100: =I94 -> 16083.99
B101: Revenue | C101: =C81 -> 145452.36 | D101: =D81 -> 135979.03 | E101: =E81 -> 156521.23 | F101: =F81 -> 183340.7 | G101: =G81 -> 221112.91 | H101: =H81 -> 255734.45 | I101: =I81 -> 285874.36
B102: Net Profit Margin(A) | C102: =C100/C101 -> 0.065650568 | D102: =D100/D101 -> 0.085181737 | E102: =E100/E101 -> 0.055387566 | F102: =F100/F101 -> 0.057110723 | G102: =G100/G101 -> 0.059060821 | H102: =H100/H101 -> 0.058799704 | I102: =I100/I101 -> 0.056262443
C104: =C99 -> 43921 | D104: =D99 -> 44286 | E104: =E99 -> 44651 | F104: =F99 -> 45016 | G104: =G99 -> 45382 | H104: =H99 -> 45747 | I104: =I99 -> 46112
B105: Revenue | C105: =C101 -> 145452.36 | D105: =D101 -> 135979.03 | E105: =E101 -> 156521.23 | F105: =F101 -> 183340.7 | G105: =G101 -> 221112.91 | H105: =H101 -> 255734.45 | I105: =I101 -> 285874.36
B106: Average Total Assets | C106: =C86 -> 292361.66 | D106: =D86 -> 308391.07 | E106: =E86 -> 314561.48 | F106: =F86 -> 324374.9 | G106: =G86 -> 334662.11 | H106: =H86 -> 359358.22 | I106: =I86 -> 415748.43
B107: Asset Turnover Ratio(B) | C107: =C105/C106 -> 0.49750833 | D107: =D105/D106 -> 0.4409305 | E107: =E105/E106 -> 0.4975855 | F107: =F105/F106 -> 0.56521236 | G107: =G105/G106 -> 0.66070494 | H107: =H105/H106 -> 0.71164214 | I107: =I105/I106 -> 0.68761381
...

Sheet HistoricalFS
B2: ="Historical Financial Statement - "&'Data Sheet'!B1 -> Historical Financial Statement - LARSEN & TOUBRO LTD
B3: Years | C3: ='Data Sheet'!B16 -> 42825 | D3: ='Data Sheet'!C16 -> 43190 | E3: ='Data Sheet'!D16 -> 43555 | F3: ='Data Sheet'!E16 -> 43921 | G3: ='Data Sheet'!F16 -> 44286 | H3: ='Data Sheet'!G16 -> 44651 | I3: ='Data Sheet'!H16 -> 45016 | J3: ='Data Sheet'!I16 -> 45382 | ... L3: ='Data Sheet'!K16 -> 46112 | M3: LTM
A5: # | B5: Income Statement
B6: Sales | C6: =IFERROR('Data Sheet'!B17,0) -> 109311.81 | D6: =IFERROR('Data Sheet'!C17,0) -> 119683.16 | E6: =IFERROR('Data Sheet'!D17,0) -> 135220.29 | F6: =IFERROR('Data Sheet'!E17,0) -> 145452.36 | G6: =IFERROR('Data Sheet'!F17,0) -> 135979.03 | H6: =IFERROR('Data Sheet'!G17,0) -> 156521.23 | I6: =IFERROR('Data Sheet'!H17,0) -> 183340.7 | J6: =IFERROR('Data Sheet'!I17,0) -> 221112.91 | ... L6: =IFERROR('Data Sheet'!K17,0) -> 285874.36 | M6: =IFERROR(SUM('Data Sheet'!H42:K42),0) -> 285874.31
B7: Sales Growth | C7: - | D7: =D6/C6-1 -> 0.094878586 | E7: =E6/D6-1 -> 0.12981885 | F7: =F6/E6-1 -> 0.075669635 | G7: =G6/F6-1 -> -0.065130122 | H7: =H6/G6-1 -> 0.15106888 | I7: =I6/H6-1 -> 0.17134717 | J7: =J6/I6-1 -> 0.20602196 | K7: =K6/J6-1 -> 0.15657856 | ... M7: =M6/L6-1 -> -1.7490201e-07
B9: COGS | C9: =IFERROR(SUM('Data Sheet'!B18,'Data Sheet'!B20:B22)-1*'Data Sheet'!B19,0) -> 84990.29 | D9: =IFERROR(SUM('Data Sheet'!C18,'Data Sheet'!C20:C22)-1*'Data Sheet'!C19,0) -> 91701.74 | E9: =IFERROR(SUM('Data Sheet'!D18,'Data Sheet'!D20:D22)-1*'Data Sheet'!D19,0) -> 104612.44 | F9: =IFERROR(SUM('Data Sheet'!E18,'Data Sheet'!E20:E22)-1*'Data Sheet'!E19,0) -> 111501.59 | G9: =IFERROR(SUM('Data Sheet'!F18,'Data Sheet'!F20:F22)-1*'Data Sheet'!F19,0) -> 103742.91 | H9: =IFERROR(SUM('Data Sheet'!G18,'Data Sheet'!G20:G22)-1*'Data Sheet'!G19,0) -> 123562.17 | I9: =IFERROR(SUM('Data Sheet'!H18,'Data Sheet'!H20:H22)-1*'Data Sheet'!H19,0) -> 147655.94 | J9: =IFERROR(SUM('Data Sheet'!I18,'Data Sheet'!I20:I22)-1*'Data Sheet'!I19,0) -> 181664.96 | ... L9: =IFERROR(SUM('Data Sheet'!K18,'Data Sheet'!K20:K22)-1*'Data Sheet'!K19,0) -> 237751.87 | M9: =IFERROR(SUM('Data Sheet'!H43:K43),0) -> 249727.83
B10: COGS % Sales | C10: =C9/C6 -> 0.77750327 | D10: =D9/D6 -> 0.7662042 | E10: =E9/E6 -> 0.77364455 | F10: =F9/F6 -> 0.76658495 | G10: =G9/G6 -> 0.76293315 | H10: =H9/H6 -> 0.78942754 | I10: =I9/I6 -> 0.80536368 | J10: =J9/J6 -> 0.82159364 | ... M10: =M9/M6 -> 0.87355814
B12: Gross Profit | C12: =C6-C9 -> 24321.52 | D12: =D6-D9 -> 27981.42 | E12: =E6-E9 -> 30607.85 | F12: =F6-F9 -> 33950.77 | G12: =G6-G9 -> 32236.12 | H12: =H6-H9 -> 32959.06 | I12: =I6-I9 -> 35684.76 | J12: =J6-J9 -> 39447.95 | ... M12: =M6-M9 -> 36146.48
B13: Gross Margins | C13: =C12/C6 -> 0.22249673 | D13: =D12/D6 -> 0.2337958 | E13: =E12/E6 -> 0.22635545 | F13: =F12/F6 -> 0.23341505 | G13: =G12/G6 -> 0.23706685 | H13: =H12/H6 -> 0.21057246 | I13: =I12/I6 -> 0.19463632 | J13: =J12/J6 -> 0.17840636 | ... M13: =M12/M6 -> 0.12644186
B15: Selling & General Expenses | C15: =IFERROR(SUM('Data Sheet'!B23:B24),0) -> 7701.11 | D15: =IFERROR(SUM('Data Sheet'!C23:C24),0) -> 7870.08 | E15: =IFERROR(SUM('Data Sheet'!D23:D24),0) -> 7742.03 | F15: =IFERROR(SUM('Data Sheet'!E23:E24),0) -> 9397.67 | G15: =IFERROR(SUM('Data Sheet'!F23:F24),0) -> 8775.88 | H15: =IFERROR(SUM('Data Sheet'!G23:G24),0) -> 8645.17 | I15: =IFERROR(SUM('Data Sheet'!H23:H24),0) -> 8518.74 | J15: =IFERROR(SUM('Data Sheet'!I23:I24),0) -> 10689.83 | ... L15: =IFERROR(SUM('Data Sheet'!K23:K24),0) -> 12711.79
B16: S&G Exp % Sales | C16: =C15/C6 -> 0.070450851 | D16: =D15/D6 -> 0.065757622 | E16: =E15/E6 -> 0.057254943 | F16: =F15/F6 -> 0.064609952 | G16: =G15/G6 -> 0.064538481 | H16: =H15/H6 -> 0.05523321 | I16: =I15/I6 -> 0.046463988 | J16: =J15/J6 -> 0.048345572 | ... M16: =M15/M6 -> 0
B18: EBITDA | C18: =C12-C15 -> 16620.41 | D18: =D12-D15 -> 20111.34 | E18: =E12-E15 -> 22865.82 | F18: =F12-F15 -> 24553.1 | G18: =G12-G15 -> 23460.24 | H18: =H12-H15 -> 24313.89 | I18: =I12-I15 -> 27166.02 | J18: =J12-J15 -> 28758.12 | ... L18: =L12-L15 -> 35410.7 | M18: =IFERROR(SUM('Data Sheet'!H51:K51),0) -> 37109.3
B19: EBITDA Margins | C19: =C18/C6 -> 0.15204588 | D19: =D18/D6 -> 0.16803818 | E19: =E18/E6 -> 0.16910051 | F19: =F18/F6 -> 0.1688051 | G19: =G18/G6 -> 0.17252837 | H19: =H18/H6 -> 0.15533925 | I19: =I18/I6 -> 0.14817234 | J19: =J18/J6 -> 0.13006079 | ... M19: =M18/M6 -> 0.12980985
B21: Interest | C21: =IFERROR('Data Sheet'!B27,0) -> 6828.66 | D21: =IFERROR('Data Sheet'!C27,0) -> 7713.63 | E21: =IFERROR('Data Sheet'!D27,0) -> 9338.73 | F21: =IFERROR('Data Sheet'!E27,0) -> 11020.78 | G21: =IFERROR('Data Sheet'!F27,0) -> 11749.58 | H21: =IFERROR('Data Sheet'!G27,0) -> 9234.98 | I21: =IFERROR('Data Sheet'!H27,0) -> 9445.44 | J21: =IFERROR('Data Sheet'!I27,0) -> 9512.17 | ... L21: =IFERROR('Data Sheet'!K27,0) -> 10055.94 | M21: =IFERROR(SUM('Data Sheet'!H46:K46),0) -> 9844.16
B22: Interest % Sales | C22: =C21/C6 -> 0.062469554 | D22: =D21/D6 -> 0.064450421 | E22: =E21/E6 -> 0.069063082 | F22: =F21/F6 -> 0.075769001 | G22: =G21/G6 -> 0.086407294 | H22: =H21/H6 -> 0.059001453 | I22: =I21/I6 -> 0.051518512 | J22: =J21/J6 -> 0.043019514 | ... M22: =M21/M6 -> 0.034435273
B24: Depreciation | C24: =IFERROR('Data Sheet'!B26,0) -> 2369.93 | D24: =IFERROR('Data Sheet'!C26,0) -> 2223.48 | E24: =IFERROR('Data Sheet'!D26,0) -> 1923.03 | F24: =IFERROR('Data Sheet'!E26,0) -> 2462.27 | G24: =IFERROR('Data Sheet'!F26,0) -> 2904.21 | H24: =IFERROR('Data Sheet'!G26,0) -> 2947.95 | I24: =IFERROR('Data Sheet'!H26,0) -> 3502.25 | J24: =IFERROR('Data Sheet'!I26,0) -> 3682.33 | ... L24: =IFERROR('Data Sheet'!K26,0) -> 4364.75 | M24: =IFERROR(SUM('Data Sheet'!H45:K45),0) -> 4364.76
B25: Depreciation%Sales | C25: =C24/C6 -> 0.021680457 | D25: =D24/D6 -> 0.018578052 | E25: =E24/E6 -> 0.01422146 | F25: =F24/F6 -> 0.016928361 | G25: =G24/G6 -> 0.021357778 | H25: =H24/H6 -> 0.018834186 | I25: =I24/I6 -> 0.019102414 | J25: =J24/J6 -> 0.016653618 | ... M25: =M24/M6 -> 0.015268109
B27: Earnings Before Tax | C27: =IFERROR(C18-SUM(C24,C21),0) -> 7421.82 | D27: =IFERROR(D18-SUM(D24,D21),0) -> 10174.23 | E27: =IFERROR(E18-SUM(E24,E21),0) -> 11604.06 | F27: =IFERROR(F18-SUM(F24,F21),0) -> 11070.05 | G27: =IFERROR(G18-SUM(G24,G21),0) -> 8806.45 | H27: =IFERROR(H18-SUM(H24,H21),0) -> 12130.96 | I27: =IFERROR(I18-SUM(I24,I21),0) -> 14218.33 | J27: =IFERROR(J18-SUM(J24,J21),0) -> 15563.62 | ... M27: =IFERROR(M18-SUM(M24,M21),0) -> 22900.38
B28: EBT % Sales | C28: =C27/C6 -> 0.067895866 | D28: =D27/D6 -> 0.085009704 | E28: =E27/E6 -> 0.085815967 | F28: =F27/F6 -> 0.076107737 | G28: =G27/G6 -> 0.064763295 | H28: =H27/H6 -> 0.077503608 | I28: =I27/I6 -> 0.077551411 | J28: =J27/J6 -> 0.070387659 | ... M28: =M27/M6 -> 0.080106464
B30: Tax | C30: =IFERROR('Data Sheet'!B29,0) -> 2006.59 | D30: =IFERROR('Data Sheet'!C29,0) -> 3198.87 | E30: =IFERROR('Data Sheet'!D29,0) -> 4067.09 | F30: =IFERROR('Data Sheet'!E29,0) -> 3263.2 | G30: =IFERROR('Data Sheet'!F29,0) -> 4010.82 | H30: =IFERROR('Data Sheet'!G29,0) -> 4203.92 | I30: =IFERROR('Data Sheet'!H29,0) -> 4484.16 | J30: =IFERROR('Data Sheet'!I29,0) -> 4947.39 | ... L30: =IFERROR('Data Sheet'!K29,0) -> 6816.41 | M30: =IFERROR(SUM('Data Sheet'!H48:K48),0) -> 6816.39
B31: Effective Tax Rate | C31: =C30/C27 -> 0.2703636 | D31: =D30/D27 -> 0.31440905 | E31: =E30/E27 -> 0.35048854 | F31: =F30/F27 -> 0.29477735 | G31: =G30/G27 -> 0.45544118 | H31: =H30/H27 -> 0.34654471 | I31: =I30/I27 -> 0.31537881 | J31: =J30/J27 -> 0.3178817 | ... M31: =M30/M27 -> 0.29765401
B33: Net Profit | C33: =IFERROR(C27-C30,0) -> 5415.23 | D33: =IFERROR(D27-D30,0) -> 6975.36 | E33: =IFERROR(E27-E30,0) -> 7536.97 | F33: =IFERROR(F27-F30,0) -> 7806.85 | G33: =IFERROR(G27-G30,0) -> 4795.63 | H33: =IFERROR(H27-H30,0) -> 7927.04 | I33: =IFERROR(I27-I30,0) -> 9734.17 | J33: =IFERROR(J27-J30,0) -> 10616.23 | ... M33: =IFERROR(M27-M30,0) -> 16083.99
B34: Net Margins | C34: =C33/C6 -> 0.049539295 | D34: =D33/D6 -> 0.058281884 | E34: =E33/E6 -> 0.055738455 | F34: =F33/F6 -> 0.0536729 | G34: =G33/G6 -> 0.035267423 | H34: =H33/H6 -> 0.050645143 | I34: =I33/I6 -> 0.053093339 | J34: =J33/J6 -> 0.04801271 | ... M34: =M33/M6 -> 0.056262453
B36: No of Equity Shares | C36: =IFERROR('Data Sheet'!B93,0) -> 139.94 | D36: =IFERROR('Data Sheet'!C93,0) -> 140.14 | E36: =IFERROR('Data Sheet'!D93,0) -> 140.27 | F36: =IFERROR('Data Sheet'!E93,0) -> 140.39 | G36: =IFERROR('Data Sheet'!F93,0) -> 140.46 | H36: =IFERROR('Data Sheet'!G93,0) -> 140.5 | I36: =IFERROR('Data Sheet'!H93,0) -> 140.55 | J36: =IFERROR('Data Sheet'!I93,0) -> 137.47 | ... L36: =IFERROR('Data Sheet'!K93,0) -> 137.56 | M36: =L36 -> 137.56
B38: Earnings per Share | C38: =IFERROR(C33/C36,0) -> 38.696799 | D38: =IFERROR(D33/D36,0) -> 49.774226 | E38: =IFERROR(E33/E36,0) -> 53.731874 | F38: =IFERROR(F33/F36,0) -> 55.608305 | G38: =IFERROR(G33/G36,0) -> 34.142318 | H38: =IFERROR(H33/H36,0) -> 56.420214 | I38: =IFERROR(I33/I36,0) -> 69.257702 | J38: =IFERROR(J33/J36,0) -> 77.225795 | ... M38: =IFERROR(M33/M36,0) -> 116.92345
B39: EPS Growth % | D39: =IFERROR(D38/C38-1,0) -> 0.28626211 | E39: =IFERROR(E38/D38-1,0) -> 0.079512005 | F39: =IFERROR(F38/E38-1,0) -> 0.034922124 | G39: =IFERROR(G38/F38-1,0) -> -0.38602125 | H39: =IFERROR(H38/G38-1,0) -> 0.65250096 | I39: =IFERROR(I38/H38-1,0) -> 0.22753349 | J39: =IFERROR(J38/I38-1,0) -> 0.11504992 | K39: =IFERROR(K38/J38-1,0) -> 0.36435174 | ... M39: =IFERROR(M38/L38-1,0) -> 0.13478509
B41: Dividend per Share | C41: =IFERROR('Data Sheet'!B31/HistoricalFS!C36,0) -> 9.3335001 | D41: =IFERROR('Data Sheet'!C31/HistoricalFS!D36,0) -> 15.999429 | E41: =IFERROR('Data Sheet'!D31/HistoricalFS!E36,0) -> 18.000642 | F41: =IFERROR('Data Sheet'!E31/HistoricalFS!F36,0) -> 18 | G41: =IFERROR('Data Sheet'!F31/HistoricalFS!G36,0) -> 35.998718 | H41: =IFERROR('Data Sheet'!G31/HistoricalFS!H36,0) -> 22.000783 | I41: =IFERROR('Data Sheet'!H31/HistoricalFS!I36,0) -> 24 | J41: =IFERROR('Data Sheet'!I31/HistoricalFS!J36,0) -> 33.998763 | ... M41: =IFERROR('Data Sheet'!L31/HistoricalFS!M36,0) -> 0
B42: Dividend payout ratio | C42: =IFERROR(C41/C38,0) -> 0.24119566 | D42: =IFERROR(D41/D38,0) -> 0.32144004 | E42: =IFERROR(E41/E38,0) -> 0.33500863 | F42: =IFERROR(F41/F38,0) -> 0.32369265 | G42: =IFERROR(G41/G38,0) -> 1.0543724 | H42: =IFERROR(H41/H38,0) -> 0.38994505 | I42: =IFERROR(I41/I38,0) -> 0.34653186 | J42: =IFERROR(J41/J38,0) -> 0.44025139 | ... M42: =IFERROR(M41/M38,0) -> 0
B44: Retained Earnings | C44: =IFERROR(IF(C38>C41,1-C42,0),0) -> 0.75880434 | D44: =IFERROR(IF(D38>D41,1-D42,0),0) -> 0.67855996 | E44: =IFERROR(IF(E38>E41,1-E42,0),0) -> 0.66499137 | F44: =IFERROR(IF(F38>F41,1-F42,0),0) -> 0.67630735 | G44: =IFERROR(IF(G38>G41,1-G42,0),0) -> 0 | H44: =IFERROR(IF(H38>H41,1-H42,0),0) -> 0.61005495 | I44: =IFERROR(IF(I38>I41,1-I42,0),0) -> 0.65346814 | J44: =IFERROR(IF(J38>J41,1-J42,0),0) -> 0.55974861 | ... M44: =IFERROR(IF(M38>M41,1-M42,0),0) -> 1
A46: # | B46: Balance Sheet
B47: Equity Share Capital | C47: =IFERROR('Data Sheet'!B57,0) -> 186.59 | D47: =IFERROR('Data Sheet'!C57,0) -> 280.27 | E47: =IFERROR('Data Sheet'!D57,0) -> 280.55 | F47: =IFERROR('Data Sheet'!E57,0) -> 280.78 | G47: =IFERROR('Data Sheet'!F57,0) -> 280.91 | H47: =IFERROR('Data Sheet'!G57,0) -> 281.01 | I47: =IFERROR('Data Sheet'!H57,0) -> 281.1 | J47: =IFERROR('Data Sheet'!I57,0) -> 274.93 | ... L47: =IFERROR('Data Sheet'!K57,0) -> 275.13
B48: Reserves | C48: =IFERROR('Data Sheet'!B58,0) -> 50029.93 | D48: =IFERROR('Data Sheet'!C58,0) -> 54623.23 | E48: =IFERROR('Data Sheet'!D58,0) -> 62094.25 | F48: =IFERROR('Data Sheet'!E58,0) -> 66442.44 | G48: =IFERROR('Data Sheet'!F58,0) -> 75587.62 | H48: =IFERROR('Data Sheet'!G58,0) -> 82126.65 | I48: =IFERROR('Data Sheet'!H58,0) -> 89044.85 | J48: =IFERROR('Data Sheet'!I58,0) -> 86084.31 | ... L48: =IFERROR('Data Sheet'!K58,0) -> 109014.67
